Workbook

Sheet Supuestos
A1: SUPUESTOS — CONTROL EN VIVO · ESCENARIO Proplasa techo 3.15 MW (PR1 557 + PR2 1,565 + TAP 1,028 kWp). Edita AZUL; recalcula todo.
A2: Cifras PRE-IVA (el IVA es acreditable para GEPP). Mecánica tarifaria = fuente primaria; ahorros = motor determinista; costos/escalaciones/PPA = supuestos.
A3: Parámetro | B3: Valor | C3: Nota / Fuente
A4: EPC PV (USD/Wp) | B4: 0.75 | C4: Llave en mano CC; supuesto MX 2026
A5: Tipo de cambio (MXN/USD) | B5: 17.55 | C5: Supuesto
A6: EPC BESS (USD/kWh) | B6: 280 | C6: LFP instalado
A7: WACC / descuento | B7: 0.12 | C7: Para VPN
A8: Escalación CFE / año | B8: 0.06 | C8: Conservador (tarifa sube)
A9: Escalación PPA / año | B9: 0.05 | C9: < CFE → brecha a favor del cliente
A10: Disponibilidad (sobre ahorro BESS) | B10: 0.75 | C10: Supuesto de downtime
A11: Degradación PV / año | B11: 0.005 | C11: TOPCon/HJT
A12: Degradación BESS / año | B12: 0.0125 | C12: LFP
A13: TIR financiador objetivo | B13: 0.18 | C13: Negociable (14–18%); las tarifas PPA semilla resuelven 18%
A14: Comisión BESS financiador (default) | B14: 0.5 | C14: Ahorro compartido (override por proyecto abajo)
A15: Horizonte (años) | B15: 20 | C15: Proyección financiera
... A24: Año de inicio del proyecto | B24: 2026 | C24: Para el escalón 2032
A26: B. VARIABLES POR PROYECTO (AZUL = editable) — afectan cada hoja de sitio, el Comparativo y la Proyección
A27: Proyecto | B27: PV kWp | C27: BESS kW | D27: BESS kWh | E27: FP corr | F27: PV USD/Wp | G27: BESS USD/kWh | H27: Capacitor capex $ | I27: PPA $/kWh | J27: PPA plazo (años) | K27: Comisión BESS % | L27: BESS (años) | M27: TIR financiador | N27: TIR compra | O27: Ahorro bruto/año $ | P27: Ahorro PPA&SAAS anual | Q27: Ahorro PPA&SAAS 20 años
A28: Ixtlahuacán | B28: 2529.67 | C28: 751.5 | D28: 1470 | E28: No | F28: 0.75 | G28: 280 | H28: 0 | I28: 1.5574 | J28: 15 | K28: 0.5 | L28: 20 | M28: =Ixtlahuacán!$G$101 -> 0.18294207 | N28: =Ixtlahuacán!$G$100 -> 0.30515621 | O28: =Ixtlahuacán!$J$72 -> 11170649 | P28: =+Ixtlahuacán!K79 -> 3573170.3 | Q28: =+Ixtlahuacán!K99 -> 2.2192145e+08
A29: Acapulco | B29: 1020.305 | C29: 250.5 | D29: 490 | E29: Sí | F29: 0.75 | G29: 280 | H29: 300000 | I29: 1.5781 | J29: 15 | K29: 0.5 | L29: 20 | M29: =Acapulco!$G$101 -> 0.18679137 | N29: =Acapulco!$G$100 -> 0.43092559 | O29: =Acapulco!$J$72 -> 6212518.3 | P29: =+Acapulco!K79 -> 3353681.3 | Q29: =+Acapulco!K99 -> 1.5759175e+08
A30: Cancún | B30: 839.41 | C30: 0 | D30: 0 | E30: Sí | F30: 0.75 | G30: 280 | H30: 250000 | I30: 1.6838 | J30: 15 | K30: 0.5 | L30: 20 | M30: =Cancún!$G$101 -> 0.18090212 | N30: =Cancún!$G$100 -> 0.43596923 | O30: =Cancún!$J$72 -> 4331791.9 | P30: =+Cancún!K79 -> 2462692.9 | Q30: =+Cancún!K99 -> 1.1291961e+08
A31: Proplasa PR1 | B31: 839.41 | C31: 501 | D31: 980 | E31: No | F31: 0.75 | G31: 280 | H31: 0 | I31: 1.5891 | J31: 15 | K31: 0.5 | L31: 20 | M31: ='Proplasa PR1'!$G$101 -> 0.18105675 | N31: ='Proplasa PR1'!$G$100 -> 0.28566512 | O31: ='Proplasa PR1'!$J$72 -> 4517195.3 | P31: =+'Proplasa PR1'!K79 -> 1246444.2 | Q31: =+'Proplasa PR1'!K99 -> 68494800
A32: Proplasa PR2 | B32: 1565.135 | C32: 1252.5 | D32: 2450 | E32: No | F32: 0.75 | G32: 280 | H32: 0 | I32: 1.6117 | J32: 15 | K32: 0.5 | L32: 20 | M32: ='Proplasa PR2'!$G$101 -> 0.17995412 | N32: ='Proplasa PR2'!$G$100 -> 0.28926483 | O32: ='Proplasa PR2'!$J$72 -> 9667366.1 | P32: =+'Proplasa PR2'!K79 -> 2748991.2 | Q32: =+'Proplasa PR2'!K99 -> 1.419215e+08
A33: Proplasa Tapas | B33: 839.41 | C33: 751.5 | D33: 1470 | E33: No | F33: 0.75 | G33: 280 | H33: 0 | I33: 1.6088 | J33: 15 | K33: 0.5 | L33: 20 | M33: ='Proplasa Tapas'!$G$101 -> 0.1784488 | N33: ='Proplasa Tapas'!$G$100 -> 0.29125501 | O33: ='Proplasa Tapas'!$J$72 -> 5506797.3 | P33: =+'Proplasa Tapas'!K79 -> 1606410.1 | Q33: =+'Proplasa Tapas'!K99 -> 80297578
A34: PORTAFOLIO | B34: =SUM(B28:B33) -> 7633.34 | D34: =SUM(D28:D33) -> 6860 | H34: =SUM(H28:H33) -> 550000 | O34: =SUM(O28:O33) -> 41406317
A36: Las tarifas PPA semilla resuelven una TIR del financiador de 18% con plazo 15 años (PV se transfiere al cliente al término) + comisión BESS 20 años. Cambia cualquier celda azul y observa el efecto en vivo.

Sheet Resumen Ejecutivo
A1: GEPP — SOLUCIÓN ENERGÉTICA · ESCENARIO: Proplasa techo 3.15 MW · Resumen Ejecutivo
A2: ESCENARIO: el techo TOTAL de Proplasa (PR1+PR2+TAP) se limita a 3.15 MW por falta de espacio (vs 10.51 MW sin límite). RECOMENDACIÓN PRIORIZADA: COMPRAR — conserva el 100% del ahorro para GEPP (más que el PPA). Cifras PRE-IVA, motor determinista. Grado prefactibilidad.
A4: INDICADORES CLAVE (PRE-IVA, año 1)
A5: Gasto eléctrico actual 2025 (CFE+autoabasto) | C5: Ahorro autoabasto (Tala+ENEL) | E5: Ahorro PV+BESS+FP (proyecto) | G5: Generación solar kWh/año
A6: ='Proyección 20 años'!C5/(1+Supuestos!$B$8) -> 2.9463417e+08 | C6: =Ixtlahuacán!$B$11+Acapulco!$B$11+Cancún!$B$11+'Proplasa PR1'!$B$11+'Proplasa PR2'!$B$11+'Proplasa Tapas'!$B$11 -> 21558824 | E6: =Ixtlahuacán!$B$21+Acapulco!$B$21+Cancún!$B$21+'Proplasa PR1'!$B$21+'Proplasa PR2'!$B$21+'Proplasa Tapas'!$B$21 -> 41406317 | G6: =Ixtlahuacán!$D$17+Acapulco!$D$17+Cancún!$D$17+'Proplasa PR1'!$D$17+'Proplasa PR2'!$D$17+'Proplasa Tapas'!$D$17 -> 13063261
A8: Inversión total (compra) | C8: Beneficio GEPP año 1 (compra) | E8: Beneficio cliente año 1 (PPA) | G8: Ahorro proyecto % vs gasto actual
A9: =Ixtlahuacán!$B$106+Acapulco!$B$106+Cancún!$B$106+'Proplasa PR1'!$B$106+'Proplasa PR2'!$B$106+'Proplasa Tapas'!$B$106 -> 1.3473388e+08 | C9: ='Comparativo Comercial'!$B$22 -> 36826414 | E9: ='Comparativo Comercial'!$E$22 -> 14991390 | G9: =$E$6/$A$6 -> 0.14053467
A11: RECOMENDACIÓN POR PROYECTO
A12: Sitio | B12: Consumo GWh/a | C12: Solución | D12: Régimen LSE | E12: Ahorro bruto a1 | F12: Ahorro % | G12: Inversión | H12: TIR compra | I12: PPA $/kWh | J12: Benef. PPA a1
A13: Ixtlahuacán | B13: 22.17 | C13: PV 2.5 MWp + BESS 850 kW | D13: Autoconsumo CNE | E13: =Ixtlahuacán!$J$72 -> 11170649 | F13: =Ixtlahuacán!$C$21 -> 0.21259287 | G13: =Ixtlahuacán!$B$106 -> 40520361 | H13: =Ixtlahuacán!$G$100 -> 0.30515621 | I13: =Supuestos!$I$28 -> 1.5574 | J13: =Ixtlahuacán!$K$79 -> 3573170.3
A14: Acapulco | B14: 8.91 | C14: FP + PV 1.0 MWp + BESS 320 kW | D14: Autoconsumo CNE | E14: =Acapulco!$J$72 -> 6212518.3 | F14: =Acapulco!$C$21 -> 0.21986264 | G14: =Acapulco!$B$106 -> 16137625 | H14: =Acapulco!$G$100 -> 0.43092559 | I14: =Supuestos!$I$29 -> 1.5781 | J14: =Acapulco!$K$79 -> 3353681.3
A15: Cancún | B15: 4.75 | C15: FP + PV 0.7 MWp (sin BESS) | D15: Exento <0.7 MW | E15: =Cancún!$J$72 -> 4331791.9 | F15: =Cancún!$C$21 -> 0.27083319 | G15: =Cancún!$B$106 -> 11298734 | H15: =Cancún!$G$100 -> 0.43596923 | I15: =Supuestos!$I$30 -> 1.6838 | J15: =Cancún!$K$79 -> 2462692.9
A16: Proplasa PR1 | B16: 16.29 | C16: PV 0.56 MWp + BESS 360 kW | D16: Autoconsumo CNE | E16: ='Proplasa PR1'!$J$72 -> 4517195.3 | F16: ='Proplasa PR1'!$C$21 -> 0.14038004 | G16: ='Proplasa PR1'!$B$106 -> 15864454 | H16: ='Proplasa PR1'!$G$100 -> 0.28566512 | I16: =Supuestos!$I$31 -> 1.5891 | J16: ='Proplasa PR1'!$K$79 -> 1246444.2
A17: Proplasa PR2 | B17: 45.72 | C17: PV 1.57 MWp + BESS 1.22 MW | D17: Autoconsumo CNE | E17: ='Proplasa PR2'!$J$72 -> 9667366.1 | F17: ='Proplasa PR2'!$C$21 -> 0.094651183 | G17: ='Proplasa PR2'!$B$106 -> 32640389 | H17: ='Proplasa PR2'!$G$100 -> 0.28926483 | I17: =Supuestos!$I$32 -> 1.6117 | J17: ='Proplasa PR2'!$K$79 -> 2748991.2
A18: Proplasa Tapas | B18: 30.03 | C18: PV 1.03 MWp + BESS 790 kW | D18: Autoconsumo CNE | E18: ='Proplasa Tapas'!$J$72 -> 5506797.3 | F18: ='Proplasa Tapas'!$C$21 -> 0.086688996 | G18: ='Proplasa Tapas'!$B$106 -> 18272314 | H18: ='Proplasa Tapas'!$G$100 -> 0.29125501 | I18: =Supuestos!$I$33 -> 1.6088 | J18: ='Proplasa Tapas'!$K$79 -> 1606410.1
A19: PORTAFOLIO | B19: =SUM(B13:B18) -> 127.87 | E19: =SUM(E13:E18) -> 41406317 | G19: =SUM(G13:G18) -> 1.3473388e+08 | J19: =SUM(J13:J18) -> 14991390
A21: Comprar maximiza el ahorro de GEPP (TIR 28-44%); el PPA/ahorro compartido es la vía sin inversión. Variables por proyecto (PPA $/kWh, plazo, costo PV/BESS) en la hoja Supuestos — todo recalcula en vivo.
A24: AUTOABASTO Y EL ESCALÓN 2032
A25: En 2025 GEPP pagó $294.6M (CFE + Tala/ENEL); a tarifa CFE plena sería $316.2M — el autoabasto ahorra ~$21.6M/año PERO VENCE 2032. ENEL ya colapsó en 2026 (Proplasa ~85% CFE), así que gran parte del salto ya ocurrió. El PV/BESS reemplaza ese ahorro con generación propia que NO expira y se vuelve más valiosa conforme sube la tarifa CFE.

Sheet Ixtlahuacán
A1: IXTLAHUACÁN — Memoria de cálculo trazable y propuesta
A2: Medidor 455GR3 · GDMTH SIN · Demanda contratada 5,000 kW · AUTOCONSUMO interconectado (>0.7 MW) — permiso SIMPLIFICADO CNE
A3: GEPP pide: Combinar autoabasto (Tala) con generación solar en sitio
A5: PARÁMETROS DEL SISTEMA (desde Supuestos — edítalos allí)
A6: PV kWp | B6: =Supuestos!$B$28 -> 2529.67 | C6: BESS kW | D6: =Supuestos!$C$28 -> 751.5 | E6: BESS kWh | F6: =Supuestos!$D$28 -> 1470 | G6: Entrega útil kWh | H6: =Supuestos!$D$28*Supuestos!$B$17*SQRT(Supuestos!$B$18) -> 1382.688 | I6: FP corr. | J6: =Supuestos!$E$28 -> No | K6: Calib→recibo | L6: =$B$10/(SUM(P45:P56)+SUM(R30:R41)) -> 1.0327958
A8: 1. ESTRUCTURA DE COSTO Y AHORRO (2025, pre-IVA · datos del workbook GEPP + motor)
A9: Concepto | B9: $ / año | C9: $ / kWh | D9: kWh | E9: Nota
A10: CFE BRUTO = Tarifa Actual (todo a CFE pleno, sin autoabasto) | B10: 55226961 | C10: =B10/D10 -> 2.4908517 | D10: 22171919 | E10: Lo que pagarían 100% en CFE sin ENEL/Tala ni PV/BESS
A11: (−) Ahorro autoabasto (Tala (bagazo, zafra)) | B11: 2682168.3 | E11: Descuento Tala 10% (dato workbook)
A12: (=) Costo actual que paga GEPP hoy | B12: =B10-B11 -> 52544793 | C12: =B12/D12 -> 2.3698802 | D12: =D10 -> 22171919
A13: › CFE (tarifa CFE plena) | B13: 28405279 | C13: =B13/D13 -> 2.5373126 | D13: 11195025
A14: › Tala (neto) | B14: 24139514 | C14: =B14/D14 -> 2.1991207 | D14: 10976894
A16: Ahorros del proyecto (motor 2025, sobre la carga física):
A17: (−) Ahorro PV (energía intermedia + demanda vía umbral) | B17: =F72 -> 9332483 | D17: =C72 -> 4511666.4 | E17: Gen solar kWh/año →
A18: (−) Ahorro BESS (recorte de punta + arbitraje) | B18: =G72 -> 1838165.5
A19: (−) Ahorro FP (corrección factor de potencia) | B19: =H72 -> 0 | E19: FP sano — sin multa
A20: (=) Costo neto con proyecto (hoy) | B20: =B12-B17-B18-B19 -> 41374144
A21: Ahorro proyecto PV+BESS+FP (vs costo hoy) | B21: =B17+B18+B19 -> 11170649 | C21: =B21/B12 -> 0.21259287
A22: Ahorro TOTAL vs CFE bruto (incl. autoabasto+proyecto) | B22: =B10-B20 -> 13852817 | C22: =B22/B10 -> 0.25083431
A24: 2. CAPEX (fórmulas vivas desde Supuestos)
A25: CAPEX PV = kWp×1000×USD/Wp×FX | B25: =$B$6*1000*Supuestos!$F$28*Supuestos!$B$5 -> 33296781 | C25: CAPEX BESS = kWh×USD/kWh×FX | D25: =$F$6*Supuestos!$G$28*Supuestos!$B$5 -> 7223580
A26: CAPEX Capacitor FP (financiador en PPA) | B26: =Supuestos!$H$28 -> 0 | C26: CAPEX TOTAL (compra) | D26: =B25+D25+B26 -> 40520361 | E26: Bajo PPA, el capacitor lo paga el financiador → el cliente no desembolsa
A28: 3. ENTRADAS MENSUALES (AZUL = datos del recibo / recurso 2025)
A29: Mes | B29: kWh Base | C29: kWh Int | D29: kWh Punta | E29: Días | F29: Dem Pta kW | G29: Dem Máx kW | H29: T.Int $ | I29: T.Base $ | J29: T.Pta $ | K29: T.Cap $ | L29: T.Dist $ | M29: T.Fijo $ | N29: Rend | O29: %AC | P29: HrsP | Q29: DíasP | R29: Bonif FP
A30: Ene | B30: 526734 | C30: 883555 | D30: 248906 | E30: 31 | F30: 3356 | G30: 3473 | H30: 1.77225 | I30: 1.078225 | J30: 2.09405 | K30: 402.07 | L30: 0 | M30: 991.97 | N30: 147.1 | O30: 1 | P30: 4 | Q30: 22 | R30: -12380.66
A31: Feb | B31: 465212 | C31: 827425 | D31: 142578 | E31: 28 | F31: 3456 | G31: 3621 | H31: 1.77225 | I31: 1.078225 | J31: 2.09405 | K31: 402.07 | L31: 0 | M31: 991.97 | N31: 142.5 | O31: 1 | P31: 4 | Q31: 19 | R31: 0
A32: Mar | B32: 716956 | C32: 1033469 | D32: 168358 | E32: 31 | F32: 3932 | G32: 3934 | H32: 1.77225 | I32: 1.078225 | J32: 2.09405 | K32: 402.07 | L32: 0 | M32: 991.97 | N32: 180.5 | O32: 1 | P32: 4 | Q32: 20 | R32: -9319.35
A33: Abr | B33: 573723 | C33: 1158862 | D33: 139082 | E33: 30 | F33: 5896 | G33: 6180 | H33: 1.77225 | I33: 1.078225 | J33: 2.09405 | K33: 402.07 | L33: 0 | M33: 991.97 | N33: 168.5 | O33: 1 | P33: 2 | Q33: 22 | R33: -5439.0278
A34: May | B34: 664426 | C34: 1271980 | D34: 118279 | E34: 31 | F34: 7008 | G34: 7508 | H34: 1.77225 | I34: 1.078225 | J34: 2.09405 | K34: 402.07 | L34: 0 | M34: 991.97 | N34: 162.7 | O34: 1 | P34: 2 | Q34: 21 | R34: 0
A35: Jun | B35: 630738 | C35: 1133752 | D35: 116822 | E35: 30 | F35: 3402 | G35: 3618 | H35: 1.77225 | I35: 1.078225 | J35: 2.09405 | K35: 402.07 | L35: 0 | M35: 991.97 | N35: 148.1 | O35: 1 | P35: 2 | Q35: 21 | R35: 0
A36: Jul | B36: 534017 | C36: 1146833 | D36: 122085 | E36: 31 | F36: 3369 | G36: 3683 | H36: 1.77225 | I36: 1.078225 | J36: 2.09405 | K36: 402.07 | L36: 0 | M36: 991.97 | N36: 138.6 | O36: 1 | P36: 2 | Q36: 23 | R36: -4632.13
A37: Ago | B37: 701321 | C37: 1065260 | D37: 176568 | E37: 31 | F37: 3760 | G37: 3819 | H37: 1.77225 | I37: 1.078225 | J37: 2.09405 | K37: 402.07 | L37: 0 | M37: 991.97 | N37: 131.7 | O37: 1 | P37: 2 | Q37: 21 | R37: 14752.23
A38: Sep | B38: 593175 | C38: 941250 | D38: 167798 | E38: 30 | F38: 3451 | G38: 3551 | H38: 1.77225 | I38: 1.078225 | J38: 2.09405 | K38: 402.07 | L38: 0 | M38: 991.97 | N38: 126.7 | O38: 1 | P38: 2 | Q38: 21 | R38: -8690.45
A39: Oct | B39: 641906 | C39: 1065460 | D39: 218540 | E39: 31 | F39: 3682 | G39: 3861 | H39: 1.77225 | I39: 1.078225 | J39: 2.09405 | K39: 402.07 | L39: 0 | M39: 991.97 | N39: 146.8 | O39: 1 | P39: 2 | Q39: 23 | R39: 6997.92
A40: Nov | B40: 719936 | C40: 965437 | D40: 254095 | E40: 30 | F40: 3754 | G40: 3846 | H40: 1.77225 | I40: 1.078225 | J40: 2.09405 | K40: 402.07 | L40: 0 | M40: 991.97 | N40: 151.9 | O40: 1 | P40: 4 | Q40: 19 | R40: 33619.41
A41: Dic | B41: 704647 | C41: 1049782 | D41: 282952 | E41: 31 | F41: 5731 | G41: 5866 | H41: 1.77225 | I41: 1.078225 | J41: 2.09405 | K41: 402.07 | L41: 0 | M41: 991.97 | N41: 138.4 | O41: 1 | P41: 4 | Q41: 22 | R41: 14.15
A42: 4. CÁLCULO DE AHORRO MENSUAL (motor — fórmulas que referencian las ENTRADAS)
A43: Mes | B43: Gen kWh | C43: Umbral kW | D43: Autocons | E43: Ah PV ener | F43: Umbral post | G43: Cap base | H43: Cap pre-B | I43: Ah PV dem | J43: Recorte BESS | K43: Cap post | L43: Ah BESS dem | M43: Desc kWh | N43: Arbitraje $ | O43: Fac.AA | P43: mem $ | Q43: Ah PV+BESS
A45: =A30 -> Ene | B45: =$B$6*N30 -> 372114.46 | C45: =(B30+C30+D30)/(E30*24*Supuestos!$B$16) -> 3912.4576 | D45: =MIN(B45*O30,C30) -> 372114.46 | E45: =D45*H30*O45 -> 593531.86 | F45: =((B30+C30+D30)-D45)/(E30*24*Supuestos!$B$16) -> 3034.9947 | G45: =MIN(F30,C45) -> 3356 | H45: =MIN(F30,F45) -> 3034.9947 | I45: =(G45-H45)*K30 -> 129066.61 | J45: =IF(P30=0,0,MIN($D$6,$H$6/P30)) -> 345.67199 | K45: =MIN(MAX(F30-J45,0),F45) -> 3010.328 | L45: =(H45-K45)*K30 -> 9917.7282 | M45: =IF(P30=0,0,MIN($H$6*Q30,D30)) -> 30419.135 | N45: =M45*J30-(M45/Supuestos!$B$18)*I30 -> 29533.907 | O45: 0.9 | P45: =M30+B30*I30+C30*H30+D30*J30+G45*K30+MIN(G30,C45)*L30 -> 4005378.6 | Q45: =(E45+I45)+(L45+N45) -> 762050.11
A46: =A31 -> Feb | B46: =$B$6*N31 -> 360477.98 | C46: =(B31+C31+D31)/(E31*24*Supuestos!$B$16) -> 3746.9063 | D46: =MIN(B46*O31,C31) -> 360477.98 | E46: =D46*H31*O46 -> 574971.38 | F46: =((B31+C31+D31)-D46)/(E31*24*Supuestos!$B$16) -> 2805.8089 | G46: =MIN(F31,C46) -> 3456 | H46: =MIN(F31,F46) -> 2805.8089 | I46: =(G46-H46)*K31 -> 261422.35 | J46: =IF(P31=0,0,MIN($D$6,$H$6/P31)) -> 345.67199 | K46: =MIN(MAX(F31-J46,0),F46) -> 2805.8089 | L46: =(H46-K46)*K31 -> 0 | M46: =IF(P31=0,0,MIN($H$6*Q31,D31)) -> 26271.071 | N46: =M46*J31-(M46/Supuestos!$B$18)*I31 -> 25506.556 | O46: 0.9 | P46: =M31+B31*I31+C31*H31+D31*J31+G46*K31+MIN(G31,C46)*L31 -> 3657118.5 | Q46: =(E46+I46)+(L46+N46) -> 861900.29
...

Sheet Acapulco
A1: ACAPULCO — Memoria de cálculo trazable y propuesta
A2: Medidor MX096Y · GDMTH SIN · Demanda contratada 2,271 kW · AUTOCONSUMO interconectado (>0.7 MW) — permiso SIMPLIFICADO CNE
A3: GEPP pide: Explorar PPA o Abasto Aislado
A5: PARÁMETROS DEL SISTEMA (desde Supuestos — edítalos allí)
A6: PV kWp | B6: =Supuestos!$B$29 -> 1020.305 | C6: BESS kW | D6: =Supuestos!$C$29 -> 250.5 | E6: BESS kWh | F6: =Supuestos!$D$29 -> 490 | G6: Entrega útil kWh | H6: =Supuestos!$D$29*Supuestos!$B$17*SQRT(Supuestos!$B$18) -> 460.89599 | I6: FP corr. | J6: =Supuestos!$E$29 -> Sí | K6: Calib→recibo | L6: =$B$10/(SUM(P45:P56)+SUM(R30:R41)) -> 1.0735938
A8: 1. ESTRUCTURA DE COSTO Y AHORRO (2025, pre-IVA · datos del workbook GEPP + motor)
A9: Concepto | B9: $ / año | C9: $ / kWh | D9: kWh | E9: Nota
A10: CFE BRUTO = Tarifa Actual (todo a CFE pleno, sin autoabasto) | B10: 28256362 | C10: =B10/D10 -> 3.1726605 | D10: 8906204 | E10: Lo que pagarían 100% en CFE sin ENEL/Tala ni PV/BESS
A11: (−) Ahorro autoabasto (—) | B11: 0 | E11: Sin autoabasto
A12: (=) Costo actual que paga GEPP hoy | B12: =B10-B11 -> 28256362 | C12: =B12/D12 -> 3.1726605 | D12: =D10 -> 8906204
A13: › CFE (tarifa CFE plena) | B13: 28256362 | C13: =B13/D13 -> 3.1726605 | D13: 8906204
A14: › sin autoabasto (100% CFE)
A16: Ahorros del proyecto (motor 2025, sobre la carga física):
A17: (−) Ahorro PV (energía intermedia + demanda vía umbral) | B17: =F72 -> 4175090 | D17: =C72 -> 1907358.2 | E17: Gen solar kWh/año →
A18: (−) Ahorro BESS (recorte de punta + arbitraje) | B18: =G72 -> 321375.64
A19: (−) Ahorro FP (corrección factor de potencia) | B19: =H72 -> 1716052.6 | E19: Multa FP impresa en el recibo (dato duro)
A20: (=) Costo neto con proyecto (hoy) | B20: =B12-B17-B18-B19 -> 22043843
A21: Ahorro proyecto PV+BESS+FP (vs costo hoy) | B21: =B17+B18+B19 -> 6212518.3 | C21: =B21/B12 -> 0.21986264
A22: Ahorro TOTAL vs CFE bruto (incl. autoabasto+proyecto) | B22: =B10-B20 -> 6212518.3 | C22: =B22/B10 -> 0.21986264
A24: 2. CAPEX (fórmulas vivas desde Supuestos)
A25: CAPEX PV = kWp×1000×USD/Wp×FX | B25: =$B$6*1000*Supuestos!$F$29*Supuestos!$B$5 -> 13429765 | C25: CAPEX BESS = kWh×USD/kWh×FX | D25: =$F$6*Supuestos!$G$29*Supuestos!$B$5 -> 2407860
A26: CAPEX Capacitor FP (financiador en PPA) | B26: =Supuestos!$H$29 -> 300000 | C26: CAPEX TOTAL (compra) | D26: =B25+D25+B26 -> 16137625 | E26: Bajo PPA, el capacitor lo paga el financiador → el cliente no desembolsa
A28: 3. ENTRADAS MENSUALES (AZUL = datos del recibo / recurso 2025)
A29: Mes | B29: kWh Base | C29: kWh Int | D29: kWh Punta | E29: Días | F29: Dem Pta kW | G29: Dem Máx kW | H29: T.Int $ | I29: T.Base $ | J29: T.Pta $ | K29: T.Cap $ | L29: T.Dist $ | M29: T.Fijo $ | N29: Rend | O29: %AC | P29: HrsP | Q29: DíasP | R29: Bonif FP
A30: Ene | B30: 195505 | C30: 377482 | D30: 103027 | E30: 31 | F30: 1540 | G30: 1666 | H30: 1.707525 | I30: 0.96695 | J30: 1.9327 | K30: 365.145 | L30: 221.09 | M30: 264.38 | N30: 159.7 | O30: 1 | P30: 4 | Q30: 22 | R30: 137543.92
A31: Feb | B31: 225267 | C31: 370816 | D31: 100217 | E31: 28 | F31: 1536 | G31: 1623 | H31: 1.707525 | I31: 0.96695 | J31: 1.9327 | K31: 365.145 | L31: 221.09 | M31: 264.38 | N31: 150.5 | O31: 1 | P31: 4 | Q31: 19 | R31: 134640.6
A32: Mar | B32: 312887 | C32: 449391 | D32: 103573 | E32: 31 | F32: 1493 | G32: 1605 | H32: 1.707525 | I32: 0.96695 | J32: 1.9327 | K32: 365.145 | L32: 221.09 | M32: 264.38 | N32: 184.5 | O32: 1 | P32: 4 | Q32: 20 | R32: 153664
A33: Abr | B33: 301373 | C33: 492059 | D33: 65557 | E33: 30 | F33: 1490 | G33: 1716 | H33: 1.707525 | I33: 0.96695 | J33: 1.9327 | K33: 365.145 | L33: 221.09 | M33: 264.38 | N33: 170.6 | O33: 1 | P33: 2 | Q33: 22 | R33: 148846.11
A34: May | B34: 312618 | C34: 506177 | D34: 49413 | E34: 31 | F34: 1582 | G34: 1715 | H34: 1.707525 | I34: 0.96695 | J34: 1.9327 | K34: 365.145 | L34: 221.09 | M34: 264.38 | N34: 166.4 | O34: 1 | P34: 2 | Q34: 21 | R34: 143046.14
A35: Jun | B35: 233673 | C35: 395913 | D35: 42282 | E35: 30 | F35: 1540 | G35: 1746 | H35: 1.707525 | I35: 0.96695 | J35: 1.9327 | K35: 365.145 | L35: 221.09 | M35: 264.38 | N35: 146.9 | O35: 1 | P35: 2 | Q35: 21 | R35: 139778.67
A36: Jul | B36: 213143 | C36: 485674 | D36: 56718 | E36: 31 | F36: 1627 | G36: 1781 | H36: 1.707525 | I36: 0.96695 | J36: 1.9327 | K36: 365.145 | L36: 221.09 | M36: 264.38 | N36: 157 | O36: 1 | P36: 2 | Q36: 23 | R36: 150698.91
A37: Ago | B37: 210539 | C37: 466847 | D37: 44577 | E37: 31 | F37: 1664 | G37: 1815 | H37: 1.707525 | I37: 0.96695 | J37: 1.9327 | K37: 365.145 | L37: 221.09 | M37: 264.38 | N37: 143.6 | O37: 1 | P37: 2 | Q37: 21 | R37: 147113.06
A38: Sep | B38: 197847 | C38: 411635 | D38: 49268 | E38: 30 | F38: 1692 | G38: 1776 | H38: 1.707525 | I38: 0.96695 | J38: 1.9327 | K38: 365.145 | L38: 221.09 | M38: 264.38 | N38: 129.8 | O38: 1 | P38: 2 | Q38: 21 | R38: 145342.3
A39: Oct | B39: 172712 | C39: 415203 | D39: 56344 | E39: 31 | F39: 1756 | G39: 1756 | H39: 1.707525 | I39: 0.96695 | J39: 1.9327 | K39: 365.145 | L39: 221.09 | M39: 264.38 | N39: 152.8 | O39: 1 | P39: 2 | Q39: 23 | R39: 135088.7
A40: Nov | B40: 248446 | C40: 348173 | D40: 86947 | E40: 30 | F40: 1638 | G40: 1734 | H40: 1.707525 | I40: 0.96695 | J40: 1.9327 | K40: 365.145 | L40: 221.09 | M40: 264.38 | N40: 154.3 | O40: 1 | P40: 4 | Q40: 19 | R40: 136386.42
A41: Dic | B41: 268553 | C41: 419527 | D41: 116821 | E41: 31 | F41: 1750 | G41: 1764 | H41: 1.707525 | I41: 0.96695 | J41: 1.9327 | K41: 365.145 | L41: 221.09 | M41: 264.38 | N41: 153.3 | O41: 1 | P41: 4 | Q41: 22 | R41: 143903.79
A42: 4. CÁLCULO DE AHORRO MENSUAL (motor — fórmulas que referencian las ENTRADAS)
A43: Mes | B43: Gen kWh | C43: Umbral kW | D43: Autocons | E43: Ah PV ener | F43: Umbral post | G43: Cap base | H43: Cap pre-B | I43: Ah PV dem | J43: Recorte BESS | K43: Cap post | L43: Ah BESS dem | M43: Desc kWh | N43: Arbitraje $ | O43: Fac.AA | P43: mem $ | Q43: Ah PV+BESS
A45: =A30 -> Ene | B45: =$B$6*N30 -> 162942.71 | C45: =(B30+C30+D30)/(E30*24*Supuestos!$B$16) -> 1594.0719 | D45: =MIN(B45*O30,C30) -> 162942.71 | E45: =D45*H30*O45 -> 278228.75 | F45: =((B30+C30+D30)-D45)/(E30*24*Supuestos!$B$16) -> 1209.8455 | G45: =MIN(F30,C45) -> 1540 | H45: =MIN(F30,F45) -> 1209.8455 | I45: =(G45-H45)*K30 -> 120554.25 | J45: =IF(P30=0,0,MIN($D$6,$H$6/P30)) -> 115.224 | K45: =MIN(MAX(F30-J45,0),F45) -> 1209.8455 | L45: =(H45-K45)*K30 -> 0 | M45: =IF(P30=0,0,MIN($H$6*Q30,D30)) -> 10139.712 | N45: =M45*J30-(M45/Supuestos!$B$18)*I30 -> 9383.9019 | O45: 1 | P45: =M30+B30*I30+C30*H30+D30*J30+G45*K30+MIN(G30,C45)*L30 -> 1947744.8 | Q45: =(E45+I45)+(L45+N45) -> 408166.9
A46: =A31 -> Feb | B46: =$B$6*N31 -> 153555.9 | C46: =(B31+C31+D31)/(E31*24*Supuestos!$B$16) -> 1817.8258 | D46: =MIN(B46*O31,C31) -> 153555.9 | E46: =D46*H31*O46 -> 262200.54 | F46: =((B31+C31+D31)-D46)/(E31*24*Supuestos!$B$16) -> 1416.9384 | G46: =MIN(F31,C46) -> 1536 | H46: =MIN(F31,F46) -> 1416.9384 | I46: =(G46-H46)*K31 -> 43474.736 | J46: =IF(P31=0,0,MIN($D$6,$H$6/P31)) -> 115.224 | K46: =MIN(MAX(F31-J46,0),F46) -> 1416.9384 | L46: =(H46-K46)*K31 -> 0 | M46: =IF(P31=0,0,MIN($H$6*Q31,D31)) -> 8757.0238 | N46: =M46*J31-(M46/Supuestos!$B$18)*I31 -> 8104.2789 | O46: 1 | P46: =M31+B31*I31+C31*H31+D31*J31+G46*K31+MIN(G31,C46)*L31 -> 1964645.1 | Q46: =(E46+I46)+(L46+N46) -> 313779.56
...

Sheet Cancún
A1: CANCÚN — Memoria de cálculo trazable y propuesta
A2: Medidor 073EEK · GDMTH SIN · Demanda contratada 1,500 kW · GENERADOR EXENTO (<0.7 MW) — Medición Neta, sin permiso
A3: GEPP pide: Explorar PPA o Abasto Aislado
A5: PARÁMETROS DEL SISTEMA (desde Supuestos — edítalos allí)
A6: PV kWp | B6: =Supuestos!$B$30 -> 839.41 | C6: BESS kW | D6: =Supuestos!$C$30 -> 0 | E6: BESS kWh | F6: =Supuestos!$D$30 -> 0 | G6: Entrega útil kWh | H6: =Supuestos!$D$30*Supuestos!$B$17*SQRT(Supuestos!$B$18) -> 0 | I6: FP corr. | J6: =Supuestos!$E$30 -> Sí | K6: Calib→recibo | L6: =$B$10/(SUM(P45:P56)+SUM(R30:R41)) -> 1.073955
A8: 1. ESTRUCTURA DE COSTO Y AHORRO (2025, pre-IVA · datos del workbook GEPP + motor)
A9: Concepto | B9: $ / año | C9: $ / kWh | D9: kWh | E9: Nota
A10: CFE BRUTO = Tarifa Actual (todo a CFE pleno, sin autoabasto) | B10: 15994317 | C10: =B10/D10 -> 3.3656431 | D10: 4752232 | E10: Lo que pagarían 100% en CFE sin ENEL/Tala ni PV/BESS
A11: (−) Ahorro autoabasto (—) | B11: 0 | E11: Sin autoabasto
A12: (=) Costo actual que paga GEPP hoy | B12: =B10-B11 -> 15994317 | C12: =B12/D12 -> 3.3656431 | D12: =D10 -> 4752232
A13: › CFE (tarifa CFE plena) | B13: 15994317 | C13: =B13/D13 -> 3.3656431 | D13: 4752232
A14: › sin autoabasto (100% CFE)
A16: Ahorros del proyecto (motor 2025, sobre la carga física):
A17: (−) Ahorro PV (energía intermedia + demanda vía umbral) | B17: =F72 -> 3734035.9 | D17: =C72 -> 1258947.1 | E17: Gen solar kWh/año →
A18: (−) Ahorro BESS (recorte de punta + arbitraje) | B18: =G72 -> 0
A19: (−) Ahorro FP (corrección factor de potencia) | B19: =H72 -> 597755.97 | E19: Multa FP impresa en el recibo (dato duro)
A20: (=) Costo neto con proyecto (hoy) | B20: =B12-B17-B18-B19 -> 11662525
A21: Ahorro proyecto PV+BESS+FP (vs costo hoy) | B21: =B17+B18+B19 -> 4331791.9 | C21: =B21/B12 -> 0.27083319
A22: Ahorro TOTAL vs CFE bruto (incl. autoabasto+proyecto) | B22: =B10-B20 -> 4331791.9 | C22: =B22/B10 -> 0.27083319
A24: 2. CAPEX (fórmulas vivas desde Supuestos)
A25: CAPEX PV = kWp×1000×USD/Wp×FX | B25: =$B$6*1000*Supuestos!$F$30*Supuestos!$B$5 -> 11048734 | C25: CAPEX BESS = kWh×USD/kWh×FX | D25: =$F$6*Supuestos!$G$30*Supuestos!$B$5 -> 0
A26: CAPEX Capacitor FP (financiador en PPA) | B26: =Supuestos!$H$30 -> 250000 | C26: CAPEX TOTAL (compra) | D26: =B25+D25+B26 -> 11298734 | E26: Bajo PPA, el capacitor lo paga el financiador → el cliente no desembolsa
A28: 3. ENTRADAS MENSUALES (AZUL = datos del recibo / recurso 2025)
A29: Mes | B29: kWh Base | C29: kWh Int | D29: kWh Punta | E29: Días | F29: Dem Pta kW | G29: Dem Máx kW | H29: T.Int $ | I29: T.Base $ | J29: T.Pta $ | K29: T.Cap $ | L29: T.Dist $ | M29: T.Fijo $ | N29: Rend | O29: %AC | P29: HrsP | Q29: DíasP | R29: Bonif FP
A30: Ene | B30: 111992 | C30: 217041 | D30: 61651 | E30: 31 | F30: 1043 | G30: 1075 | H30: 2.08045 | I30: 1.23575 | J30: 2.321525 | K30: 392.485 | L30: 91.87 | M30: 452.58 | N30: 116.3 | O30: 1 | P30: 4 | Q30: 22 | R30: 49039.23
A31: Feb | B31: 119044 | C31: 193524 | D31: 57902 | E31: 28 | F31: 1010 | G31: 1068 | H31: 2.08045 | I31: 1.23575 | J31: 2.321525 | K31: 392.485 | L31: 91.87 | M31: 452.58 | N31: 113.8 | O31: 1 | P31: 4 | Q31: 19 | R31: 45533.52
A32: Mar | B32: 143269 | C32: 218315 | D32: 57204 | E32: 31 | F32: 930 | G32: 995 | H32: 2.08045 | I32: 1.23575 | J32: 2.321525 | K32: 392.485 | L32: 91.87 | M32: 452.58 | N32: 140.6 | O32: 1 | P32: 4 | Q32: 20 | R32: 44271.61
A33: Abr | B33: 137235 | C33: 257107 | D33: 37859 | E33: 30 | F33: 934 | G33: 986 | H33: 2.08045 | I33: 1.23575 | J33: 2.321525 | K33: 392.485 | L33: 91.87 | M33: 452.58 | N33: 139.9 | O33: 1 | P33: 2 | Q33: 22 | R33: 47050.61
A34: May | B34: 131219 | C34: 271299 | D34: 30661 | E34: 31 | F34: 1094 | G34: 1130 | H34: 2.08045 | I34: 1.23575 | J34: 2.321525 | K34: 392.485 | L34: 91.87 | M34: 452.58 | N34: 139.6 | O34: 1 | P34: 2 | Q34: 21 | R34: 48308.02
A35: Jun | B35: 135885 | C35: 268040 | D35: 30139 | E35: 30 | F35: 1049 | G35: 1092 | H35: 2.08045 | I35: 1.23575 | J35: 2.321525 | K35: 392.485 | L35: 91.87 | M35: 452.58 | N35: 127.4 | O35: 1 | P35: 2 | Q35: 21 | R35: 55431.62
A36: Jul | B36: 101439 | C36: 274792 | D36: 34785 | E36: 31 | F36: 1092 | G36: 1103 | H36: 2.08045 | I36: 1.23575 | J36: 2.321525 | K36: 392.485 | L36: 91.87 | M36: 452.58 | N36: 131.2 | O36: 1 | P36: 2 | Q36: 23 | R36: 55104.56
A37: Ago | B37: 116365 | C37: 275738 | D37: 28280 | E37: 31 | F37: 1051 | G37: 1097 | H37: 2.08045 | I37: 1.23575 | J37: 2.321525 | K37: 392.485 | L37: 91.87 | M37: 452.58 | N37: 123.3 | O37: 1 | P37: 2 | Q37: 21 | R37: 53076.82
A38: Sep | B38: 100169 | C38: 231786 | D38: 26471 | E38: 30 | F38: 1014 | G38: 1066 | H38: 2.08045 | I38: 1.23575 | J38: 2.321525 | K38: 392.485 | L38: 91.87 | M38: 452.58 | N38: 118.3 | O38: 1 | P38: 2 | Q38: 21 | R38: 49101.31
A39: Oct | B39: 98572 | C39: 224586 | D39: 35922 | E39: 31 | F39: 913 | G39: 958 | H39: 2.08045 | I39: 1.23575 | J39: 2.321525 | K39: 392.485 | L39: 91.87 | M39: 452.58 | N39: 121.8 | O39: 1 | P39: 2 | Q39: 23 | R39: 53035.23
A40: Nov | B40: 94126 | C40: 183552 | D40: 53993 | E40: 30 | F40: 939 | G40: 968 | H40: 2.08045 | I40: 1.23575 | J40: 2.321525 | K40: 392.485 | L40: 91.87 | M40: 452.58 | N40: 115 | O40: 1 | P40: 4 | Q40: 19 | R40: 47771.27
A41: Dic | B41: 102510 | C41: 225061 | D41: 64699 | E41: 31 | F41: 960 | G41: 971 | H41: 2.08045 | I41: 1.23575 | J41: 2.321525 | K41: 392.485 | L41: 91.87 | M41: 452.58 | N41: 112.6 | O41: 1 | P41: 4 | Q41: 22 | R41: 50032.17
A42: 4. CÁLCULO DE AHORRO MENSUAL (motor — fórmulas que referencian las ENTRADAS)
A43: Mes | B43: Gen kWh | C43: Umbral kW | D43: Autocons | E43: Ah PV ener | F43: Umbral post | G43: Cap base | H43: Cap pre-B | I43: Ah PV dem | J43: Recorte BESS | K43: Cap post | L43: Ah BESS dem | M43: Desc kWh | N43: Arbitraje $ | O43: Fac.AA | P43: mem $ | Q43: Ah PV+BESS
A45: =A30 -> Ene | B45: =$B$6*N30 -> 97623.383 | C45: =(B30+C30+D30)/(E30*24*Supuestos!$B$16) -> 921.25071 | D45: =MIN(B45*O30,C30) -> 97623.383 | E45: =D45*H30*O45 -> 203100.57 | F45: =((B30+C30+D30)-D45)/(E30*24*Supuestos!$B$16) -> 691.05031 | G45: =MIN(F30,C45) -> 921.25071 | H45: =MIN(F30,F45) -> 691.05031 | I45: =(G45-H45)*K30 -> 90350.202 | J45: =IF(P30=0,0,MIN($D$6,$H$6/P30)) -> 0 | K45: =MIN(MAX(F30-J45,0),F45) -> 691.05031 | L45: =(H45-K45)*K30 -> 0 | M45: =IF(P30=0,0,MIN($H$6*Q30,D30)) -> 0 | N45: =M45*J30-(M45/Supuestos!$B$18)*I30 -> 0 | O45: 1 | P45: =M30+B30*I30+C30*H30+D30*J30+G45*K30+MIN(G30,C45)*L30 -> 1179726.4 | Q45: =(E45+I45)+(L45+N45) -> 293450.77
A46: =A31 -> Feb | B46: =$B$6*N31 -> 95524.858 | C46: =(B31+C31+D31)/(E31*24*Supuestos!$B$16) -> 967.18358 | D46: =MIN(B46*O31,C31) -> 95524.858 | E46: =D46*H31*O46 -> 198734.69 | F46: =((B31+C31+D31)-D46)/(E31*24*Supuestos!$B$16) -> 717.79747 | G46: =MIN(F31,C46) -> 967.18358 | H46: =MIN(F31,F46) -> 717.79747 | I46: =(G46-H46)*K31 -> 97880.31 | J46: =IF(P31=0,0,MIN($D$6,$H$6/P31)) -> 0 | K46: =MIN(MAX(F31-J46,0),F46) -> 717.79747 | L46: =(H46-K46)*K31 -> 0 | M46: =IF(P31=0,0,MIN($H$6*Q31,D31)) -> 0 | N46: =M46*J31-(M46/Supuestos!$B$18)*I31 -> 0 | O46: 1 | P46: =M31+B31*I31+C31*H31+D31*J31+G46*K31+MIN(G31,C46)*L31 -> 1153059.4 | Q46: =(E46+I46)+(L46+N46) -> 296615
...

Sheet Proplasa PR1
A1: PROPLASA PR1 — Memoria de cálculo trazable y propuesta
A2: Medidor 806DYN · GDMTH SIN · Demanda contratada 2,600 kW · AUTOCONSUMO interconectado (>0.7 MW) — permiso SIMPLIFICADO CNE
A3: GEPP pide: Combinar autoabasto (ENEL) con generación solar en sitio
A5: PARÁMETROS DEL SISTEMA (desde Supuestos — edítalos allí)
A6: PV kWp | B6: =Supuestos!$B$31 -> 839.41 | C6: BESS kW | D6: =Supuestos!$C$31 -> 501 | E6: BESS kWh | F6: =Supuestos!$D$31 -> 980 | G6: Entrega útil kWh | H6: =Supuestos!$D$31*Supuestos!$B$17*SQRT(Supuestos!$B$18) -> 921.79198 | I6: FP corr. | J6: =Supuestos!$E$31 -> No | K6: Calib→recibo | L6: =$B$10/(SUM(P45:P56)+SUM(R30:R41)) -> 1
A8: 1. ESTRUCTURA DE COSTO Y AHORRO (2025, pre-IVA · datos del workbook GEPP + motor)
A9: Concepto | B9: $ / año | C9: $ / kWh | D9: kWh | E9: Nota
A10: CFE BRUTO = Tarifa Actual (todo a CFE pleno, sin autoabasto) | B10: 36585609 | C10: =B10/D10 -> 2.2459909 | D10: 16289295 | E10: Lo que pagarían 100% en CFE sin ENEL/Tala ni PV/BESS
A11: (−) Ahorro autoabasto (ENEL) | B11: 4407279.5 | E11: Beneficio ENEL ($1.78/kWh vs CFE; validado por colapso 2026)
A12: (=) Costo actual que paga GEPP hoy | B12: =B10-B11 -> 32178329 | C12: =B12/D12 -> 1.975428 | D12: =D10 -> 16289295
A13: › CFE (tarifa CFE plena) | B13: 5255585.9 | C13: =B13/D13 -> 2.4595534 | D13: 2136805
A14: › ENEL | B14: 26922743 | C14: =B14/D14 -> 1.9023326 | D14: 14152490
A15: › Mezcla de suministro 2025 | B15: =D13/D12 -> 0.13117848 | C15: CFE | D15: =D14/D12 -> 0.86882152 | E15: ENEL (en 2026 ENEL ya colapsó → CFE ~85%)
A16: Ahorros del proyecto (motor 2025, sobre la carga física):
A17: (−) Ahorro PV (energía intermedia + demanda vía umbral) | B17: =F72 -> 2532058.3 | D17: =C72 -> 1393504.5 | E17: Gen solar kWh/año →
A18: (−) Ahorro BESS (recorte de punta + arbitraje) | B18: =G72 -> 1985137
A19: (−) Ahorro FP (corrección factor de potencia) | B19: =H72 -> 0 | E19: FP sano — sin multa
A20: (=) Costo neto con proyecto (hoy) | B20: =B12-B17-B18-B19 -> 27661134
A21: Ahorro proyecto PV+BESS+FP (vs costo hoy) | B21: =B17+B18+B19 -> 4517195.3 | C21: =B21/B12 -> 0.14038004
A22: Ahorro TOTAL vs CFE bruto (incl. autoabasto+proyecto) | B22: =B10-B20 -> 8924474.8 | C22: =B22/B10 -> 0.24393403
A24: 2. CAPEX (fórmulas vivas desde Supuestos)
A25: CAPEX PV = kWp×1000×USD/Wp×FX | B25: =$B$6*1000*Supuestos!$F$31*Supuestos!$B$5 -> 11048734 | C25: CAPEX BESS = kWh×USD/kWh×FX | D25: =$F$6*Supuestos!$G$31*Supuestos!$B$5 -> 4815720
A26: CAPEX Capacitor FP (financiador en PPA) | B26: =Supuestos!$H$31 -> 0 | C26: CAPEX TOTAL (compra) | D26: =B25+D25+B26 -> 15864454 | E26: Bajo PPA, el capacitor lo paga el financiador → el cliente no desembolsa
A28: 3. ENTRADAS MENSUALES (AZUL = datos del recibo / recurso 2025)
A29: Mes | B29: kWh Base | C29: kWh Int | D29: kWh Punta | E29: Días | F29: Dem Pta kW | G29: Dem Máx kW | H29: T.Int $ | I29: T.Base $ | J29: T.Pta $ | K29: T.Cap $ | L29: T.Dist $ | M29: T.Fijo $ | N29: Rend | O29: %AC | P29: HrsP | Q29: DíasP | R29: Bonif FP
A30: Ene | B30: 455237 | C30: 729971 | D30: 183178 | E30: 31 | F30: 1892 | G30: 1930 | H30: 1.819675 | I30: 1.10665 | J30: 2.1272 | K30: 402.0725 | L30: 86.15 | M30: 703.36 | N30: 142.8 | O30: 1 | P30: 4 | Q30: 22 | R30: 0
A31: Feb | B31: 476589 | C31: 681958 | D31: 167798 | E31: 28 | F31: 1903 | G31: 1936 | H31: 1.819675 | I31: 1.10665 | J31: 2.1272 | K31: 402.0725 | L31: 86.15 | M31: 703.36 | N31: 139.1 | O31: 1 | P31: 4 | Q31: 19 | R31: 0
A32: Mar | B32: 535513 | C32: 750251 | D32: 182294 | E32: 31 | F32: 1771 | G32: 1793 | H32: 1.819675 | I32: 1.10665 | J32: 2.1272 | K32: 402.0725 | L32: 86.15 | M32: 703.36 | N32: 170.1 | O32: 1 | P32: 4 | Q32: 20 | R32: 0
A33: Abr | B33: 497333 | C33: 867045 | D33: 108027 | E33: 30 | F33: 1579 | G33: 1622 | H33: 1.819675 | I33: 1.10665 | J33: 2.1272 | K33: 402.0725 | L33: 86.15 | M33: 703.36 | N33: 150.7 | O33: 1 | P33: 2 | Q33: 22 | R33: -15843.7
A34: May | B34: 546627 | C34: 924218 | D34: 89553 | E34: 31 | F34: 1654 | G34: 1700 | H34: 1.819675 | I34: 1.10665 | J34: 2.1272 | K34: 402.0725 | L34: 86.15 | M34: 703.36 | N34: 143.1 | O34: 1 | P34: 2 | Q34: 21 | R34: -18059.94
A35: Jun | B35: 467527 | C35: 810870 | D35: 82141 | E35: 30 | F35: 1465 | G35: 1532 | H35: 1.819675 | I35: 1.10665 | J35: 2.1272 | K35: 402.0725 | L35: 86.15 | M35: 703.36 | N35: 133.9 | O35: 1 | P35: 2 | Q35: 21 | R35: -6803.62
A36: Jul | B36: 414209 | C36: 746631 | D36: 74300 | E36: 31 | F36: 1582 | G36: 1672 | H36: 1.819675 | I36: 1.10665 | J36: 2.1272 | K36: 402.0725 | L36: 86.15 | M36: 703.36 | N36: 135.2 | O36: 1 | P36: 2 | Q36: 23 | R36: -3279.85
A37: Ago | B37: 511027 | C37: 868483 | D37: 84864 | E37: 31 | F37: 1515 | G37: 1568 | H37: 1.819675 | I37: 1.10665 | J37: 2.1272 | K37: 402.0725 | L37: 86.15 | M37: 703.36 | N37: 126.5 | O37: 1 | P37: 2 | Q37: 21 | R37: -8395.35
A38: Sep | B38: 471225 | C38: 799977 | D38: 80458 | E38: 30 | F38: 2279 | G38: 2356 | H38: 1.819675 | I38: 1.10665 | J38: 2.1272 | K38: 402.0725 | L38: 86.15 | M38: 703.36 | N38: 119.5 | O38: 1 | P38: 2 | Q38: 21 | R38: -486.12
A39: Oct | B39: 435183 | C39: 788394 | D39: 98384 | E39: 31 | F39: 1750 | G39: 1832 | H39: 1.819675 | I39: 1.10665 | J39: 2.1272 | K39: 402.0725 | L39: 86.15 | M39: 703.36 | N39: 131.7 | O39: 1 | P39: 2 | Q39: 23 | R39: -289.26
A40: Nov | B40: 431457 | C40: 617240 | D40: 150654 | E40: 30 | F40: 2026 | G40: 2026 | H40: 1.819675 | I40: 1.10665 | J40: 2.1272 | K40: 402.0725 | L40: 86.15 | M40: 703.36 | N40: 136.6 | O40: 1 | P40: 4 | Q40: 19 | R40: 0
A41: Dic | B41: 395911 | C41: 618556 | D41: 146212 | E41: 31 | F41: 2124 | G41: 2124 | H41: 1.819675 | I41: 1.10665 | J41: 2.1272 | K41: 402.0725 | L41: 86.15 | M41: 703.36 | N41: 130.9 | O41: 1 | P41: 4 | Q41: 22 | R41: -12.55
A42: 4. CÁLCULO DE AHORRO MENSUAL (motor — fórmulas que referencian las ENTRADAS)
A43: Mes | B43: Gen kWh | C43: Umbral kW | D43: Autocons | E43: Ah PV ener | F43: Umbral post | G43: Cap base | H43: Cap pre-B | I43: Ah PV dem | J43: Recorte BESS | K43: Cap post | L43: Ah BESS dem | M43: Desc kWh | N43: Arbitraje $ | O43: Fac.AA | P43: mem $ | Q43: Ah PV+BESS
A45: =A30 -> Ene | B45: =$B$6*N30 -> 119867.75 | C45: =(B30+C30+D30)/(E30*24*Supuestos!$B$16) -> 3226.7167 | D45: =MIN(B45*O30,C30) -> 119867.75 | E45: =D45*H30*O45 -> 218120.34 | F45: =((B30+C30+D30)-D45)/(E30*24*Supuestos!$B$16) -> 2944.063 | G45: =MIN(F30,C45) -> 1892 | H45: =MIN(F30,F45) -> 1892 | I45: =(G45-H45)*K30 -> 0 | J45: =IF(P30=0,0,MIN($D$6,$H$6/P30)) -> 230.448 | K45: =MIN(MAX(F30-J45,0),F45) -> 1661.552 | L45: =(H45-K45)*K30 -> 92656.801 | M45: =IF(P30=0,0,MIN($H$6*Q30,D30)) -> 20279.424 | N45: =M45*J30-(M45/Supuestos!$B$18)*I30 -> 19761.073 | O45: 1 | P45: =M30+B30*I30+C30*H30+D30*J30+G45*K30+MIN(G30,C45)*L30 -> 3149448.3 | Q45: =(E45+I45)+(L45+N45) -> 330538.22
...

Sheet Proplasa PR2
A1: PROPLASA PR2 — Memoria de cálculo trazable y propuesta
A2: Medidor 805DYN · GDMTH SIN · Demanda contratada 5,625 kW · AUTOCONSUMO interconectado (>0.7 MW) — permiso SIMPLIFICADO CNE
A3: GEPP pide: Combinar autoabasto (ENEL) con generación solar en sitio
A5: PARÁMETROS DEL SISTEMA (desde Supuestos — edítalos allí)
A6: PV kWp | B6: =Supuestos!$B$32 -> 1565.135 | C6: BESS kW | D6: =Supuestos!$C$32 -> 1252.5 | E6: BESS kWh | F6: =Supuestos!$D$32 -> 2450 | G6: Entrega útil kWh | H6: =Supuestos!$D$32*Supuestos!$B$17*SQRT(Supuestos!$B$18) -> 2304.48 | I6: FP corr. | J6: =Supuestos!$E$32 -> No | K6: Calib→recibo | L6: =$B$10/(SUM(P45:P56)+SUM(R30:R41)) -> 1
A8: 1. ESTRUCTURA DE COSTO Y AHORRO (2025, pre-IVA · datos del workbook GEPP + motor)
A9: Concepto | B9: $ / año | C9: $ / kWh | D9: kWh | E9: Nota
A10: CFE BRUTO = Tarifa Actual (todo a CFE pleno, sin autoabasto) | B10: 1.088104e+08 | C10: =B10/D10 -> 2.3799542 | D10: 45719537 | E10: Lo que pagarían 100% en CFE sin ENEL/Tala ni PV/BESS
A11: (−) Ahorro autoabasto (ENEL) | B11: 6673632.8 | E11: Beneficio ENEL ($1.78/kWh vs CFE; validado por colapso 2026)
A12: (=) Costo actual que paga GEPP hoy | B12: =B10-B11 -> 1.0213677e+08 | C12: =B12/D12 -> 2.2339852 | D12: =D10 -> 45719537
A13: › CFE (tarifa CFE plena) | B13: 55799375 | C13: =B13/D13 -> 2.8304056 | D13: 19714268
A14: › ENEL | B14: 46337395 | C14: =B14/D14 -> 1.7818464 | D14: 26005269
A15: › Mezcla de suministro 2025 | B15: =D13/D12 -> 0.43120008 | C15: CFE | D15: =D14/D12 -> 0.56879992 | E15: ENEL (en 2026 ENEL ya colapsó → CFE ~85%)
A16: Ahorros del proyecto (motor 2025, sobre la carga física):
A17: (−) Ahorro PV (energía intermedia + demanda vía umbral) | B17: =F72 -> 4713237.5 | D17: =C72 -> 2598280.6 | E17: Gen solar kWh/año →
A18: (−) Ahorro BESS (recorte de punta + arbitraje) | B18: =G72 -> 4954128.6
A19: (−) Ahorro FP (corrección factor de potencia) | B19: =H72 -> 0 | E19: FP sano — sin multa
A20: (=) Costo neto con proyecto (hoy) | B20: =B12-B17-B18-B19 -> 92469404
A21: Ahorro proyecto PV+BESS+FP (vs costo hoy) | B21: =B17+B18+B19 -> 9667366.1 | C21: =B21/B12 -> 0.094651183
A22: Ahorro TOTAL vs CFE bruto (incl. autoabasto+proyecto) | B22: =B10-B20 -> 16340999 | C22: =B22/B10 -> 0.15017865
A24: 2. CAPEX (fórmulas vivas desde Supuestos)
A25: CAPEX PV = kWp×1000×USD/Wp×FX | B25: =$B$6*1000*Supuestos!$F$32*Supuestos!$B$5 -> 20601089 | C25: CAPEX BESS = kWh×USD/kWh×FX | D25: =$F$6*Supuestos!$G$32*Supuestos!$B$5 -> 12039300
A26: CAPEX Capacitor FP (financiador en PPA) | B26: =Supuestos!$H$32 -> 0 | C26: CAPEX TOTAL (compra) | D26: =B25+D25+B26 -> 32640389 | E26: Bajo PPA, el capacitor lo paga el financiador → el cliente no desembolsa
A28: 3. ENTRADAS MENSUALES (AZUL = datos del recibo / recurso 2025)
A29: Mes | B29: kWh Base | C29: kWh Int | D29: kWh Punta | E29: Días | F29: Dem Pta kW | G29: Dem Máx kW | H29: T.Int $ | I29: T.Base $ | J29: T.Pta $ | K29: T.Cap $ | L29: T.Dist $ | M29: T.Fijo $ | N29: Rend | O29: %AC | P29: HrsP | Q29: DíasP | R29: Bonif FP
A30: Ene | B30: 1127389 | C30: 1795542 | D30: 466031 | E30: 31 | F30: 6670 | G30: 6718 | H30: 1.819675 | I30: 1.10665 | J30: 2.1272 | K30: 402.0725 | L30: 86.15 | M30: 703.36 | N30: 142.8 | O30: 1 | P30: 4 | Q30: 22 | R30: -3068.41
A31: Feb | B31: 1258745 | C31: 1870728 | D31: 471567 | E31: 28 | F31: 6525 | G31: 6557 | H31: 1.819675 | I31: 1.10665 | J31: 2.1272 | K31: 402.0725 | L31: 86.15 | M31: 703.36 | N31: 139.1 | O31: 1 | P31: 4 | Q31: 19 | R31: -1746.75
A32: Mar | B32: 1582579 | C32: 2238743 | D32: 538917 | E32: 31 | F32: 6470 | G32: 6470 | H32: 1.819675 | I32: 1.10665 | J32: 2.1272 | K32: 402.0725 | L32: 86.15 | M32: 703.36 | N32: 170.1 | O32: 1 | P32: 4 | Q32: 20 | R32: -2882.66
A33: Abr | B33: 1391931 | C33: 2472488 | D33: 308716 | E33: 30 | F33: 6489 | G33: 6597 | H33: 1.819675 | I33: 1.10665 | J33: 2.1272 | K33: 402.0725 | L33: 86.15 | M33: 703.36 | N33: 150.7 | O33: 1 | P33: 2 | Q33: 22 | R33: -5739.34
A34: May | B34: 1554976 | C34: 2674916 | D34: 252409 | E34: 31 | F34: 6509 | G34: 6565 | H34: 1.819675 | I34: 1.10665 | J34: 2.1272 | K34: 402.0725 | L34: 86.15 | M34: 703.36 | N34: 143.1 | O34: 1 | P34: 2 | Q34: 21 | R34: -9014.39
A35: Jun | B35: 1461034 | C35: 2511016 | D35: 251483 | E35: 30 | F35: 6634 | G35: 6744 | H35: 1.819675 | I35: 1.10665 | J35: 2.1272 | K35: 402.0725 | L35: 86.15 | M35: 703.36 | N35: 133.9 | O35: 1 | P35: 2 | Q35: 21 | R35: -31375.9
A36: Jul | B36: 1213977 | C36: 2229430 | D36: 229493 | E36: 31 | F36: 5851 | G36: 5873 | H36: 1.819675 | I36: 1.10665 | J36: 2.1272 | K36: 402.0725 | L36: 86.15 | M36: 703.36 | N36: 135.2 | O36: 1 | P36: 2 | Q36: 23 | R36: -47885.63
A37: Ago | B37: 1460355 | C37: 2480903 | D37: 235656 | E37: 31 | F37: 6354 | G37: 6492 | H37: 1.819675 | I37: 1.10665 | J37: 2.1272 | K37: 402.0725 | L37: 86.15 | M37: 703.36 | N37: 126.5 | O37: 1 | P37: 2 | Q37: 21 | R37: -45455.49
A38: Sep | B38: 1257774 | C38: 2130853 | D38: 208228 | E38: 30 | F38: 5562 | G38: 6311 | H38: 1.819675 | I38: 1.10665 | J38: 2.1272 | K38: 402.0725 | L38: 86.15 | M38: 703.36 | N38: 119.5 | O38: 1 | P38: 2 | Q38: 21 | R38: -48968.46
A39: Oct | B39: 1080780 | C39: 2010757 | D39: 247787 | E39: 31 | F39: 4470 | G39: 4522 | H39: 1.819675 | I39: 1.10665 | J39: 2.1272 | K39: 402.0725 | L39: 86.15 | M39: 703.36 | N39: 131.7 | O39: 1 | P39: 2 | Q39: 23 | R39: -53687.85
A40: Nov | B40: 1215444 | C40: 1781412 | D40: 435452 | E40: 30 | F40: 6123 | G40: 6215 | H40: 1.819675 | I40: 1.10665 | J40: 2.1272 | K40: 402.0725 | L40: 86.15 | M40: 703.36 | N40: 136.6 | O40: 1 | P40: 4 | Q40: 19 | R40: -48131.55
A41: Dic | B41: 1136000 | C41: 1717671 | D41: 418355 | E41: 31 | F41: 5588 | G41: 6070 | H41: 1.819675 | I41: 1.10665 | J41: 2.1272 | K41: 402.0725 | L41: 86.15 | M41: 703.36 | N41: 130.9 | O41: 1 | P41: 4 | Q41: 22 | R41: -43469.54
A42: 4. CÁLCULO DE AHORRO MENSUAL (motor — fórmulas que referencian las ENTRADAS)
A43: Mes | B43: Gen kWh | C43: Umbral kW | D43: Autocons | E43: Ah PV ener | F43: Umbral post | G43: Cap base | H43: Cap pre-B | I43: Ah PV dem | J43: Recorte BESS | K43: Cap post | L43: Ah BESS dem | M43: Desc kWh | N43: Arbitraje $ | O43: Fac.AA | P43: mem $ | Q43: Ah PV+BESS
A45: =A30 -> Ene | B45: =$B$6*N30 -> 223501.28 | C45: =(B30+C30+D30)/(E30*24*Supuestos!$B$16) -> 7991.3271 | D45: =MIN(B45*O30,C30) -> 223501.28 | E45: =D45*H30*O45 -> 406699.69 | F45: =((B30+C30+D30)-D45)/(E30*24*Supuestos!$B$16) -> 7464.3009 | G45: =MIN(F30,C45) -> 6670 | H45: =MIN(F30,F45) -> 6670 | I45: =(G45-H45)*K30 -> 0 | J45: =IF(P30=0,0,MIN($D$6,$H$6/P30)) -> 576.11999 | K45: =MIN(MAX(F30-J45,0),F45) -> 6093.88 | L45: =(H45-K45)*K30 -> 231642 | M45: =IF(P30=0,0,MIN($H$6*Q30,D30)) -> 50698.559 | N45: =M45*J30-(M45/Supuestos!$B$18)*I30 -> 49402.683 | O45: 1 | P45: =M30+B30*I30+C30*H30+D30*J30+G45*K30+MIN(G30,C45)*L30 -> 8767551.7 | Q45: =(E45+I45)+(L45+N45) -> 687744.37
...

Sheet Proplasa Tapas
A1: PROPLASA TAPAS — Memoria de cálculo trazable y propuesta
A2: Medidor 807DYN · GDMTH SIN · Demanda contratada 2,814 kW · AUTOCONSUMO interconectado (>0.7 MW) — permiso SIMPLIFICADO CNE
A3: GEPP pide: Combinar autoabasto (ENEL) con generación solar en sitio
A5: PARÁMETROS DEL SISTEMA (desde Supuestos — edítalos allí)
A6: PV kWp | B6: =Supuestos!$B$33 -> 839.41 | C6: BESS kW | D6: =Supuestos!$C$33 -> 751.5 | E6: BESS kWh | F6: =Supuestos!$D$33 -> 1470 | G6: Entrega útil kWh | H6: =Supuestos!$D$33*Supuestos!$B$17*SQRT(Supuestos!$B$18) -> 1382.688 | I6: FP corr. | J6: =Supuestos!$E$33 -> No | K6: Calib→recibo | L6: =$B$10/(SUM(P45:P56)+SUM(R30:R41)) -> 1
A8: 1. ESTRUCTURA DE COSTO Y AHORRO (2025, pre-IVA · datos del workbook GEPP + motor)
A9: Concepto | B9: $ / año | C9: $ / kWh | D9: kWh | E9: Nota
A10: CFE BRUTO = Tarifa Actual (todo a CFE pleno, sin autoabasto) | B10: 71319345 | C10: =B10/D10 -> 2.3752187 | D10: 30026433 | E10: Lo que pagarían 100% en CFE sin ENEL/Tala ni PV/BESS
A11: (−) Ahorro autoabasto (ENEL) | B11: 7795742.9 | E11: Beneficio ENEL ($1.78/kWh vs CFE; validado por colapso 2026)
A12: (=) Costo actual que paga GEPP hoy | B12: =B10-B11 -> 63523603 | C12: =B12/D12 -> 2.1155894 | D12: =D10 -> 30026433
A13: › CFE (tarifa CFE plena) | B13: 17688145 | C13: =B13/D13 -> 2.8652615 | D13: 6173309
A14: › ENEL | B14: 45835458 | C14: =B14/D14 -> 1.9215704 | D14: 23853124
A15: › Mezcla de suministro 2025 | B15: =D13/D12 -> 0.20559582 | C15: CFE | D15: =D14/D12 -> 0.79440418 | E15: ENEL (en 2026 ENEL ya colapsó → CFE ~85%)
A16: Ahorros del proyecto (motor 2025, sobre la carga física):
A17: (−) Ahorro PV (energía intermedia + demanda vía umbral) | B17: =F72 -> 2530292.8 | D17: =C72 -> 1393504.5 | E17: Gen solar kWh/año →
A18: (−) Ahorro BESS (recorte de punta + arbitraje) | B18: =G72 -> 2976504.5
A19: (−) Ahorro FP (corrección factor de potencia) | B19: =H72 -> 0 | E19: FP sano — sin multa
A20: (=) Costo neto con proyecto (hoy) | B20: =B12-B17-B18-B19 -> 58016805
A21: Ahorro proyecto PV+BESS+FP (vs costo hoy) | B21: =B17+B18+B19 -> 5506797.3 | C21: =B21/B12 -> 0.086688996
A22: Ahorro TOTAL vs CFE bruto (incl. autoabasto+proyecto) | B22: =B10-B20 -> 13302540 | C22: =B22/B10 -> 0.18652078
A24: 2. CAPEX (fórmulas vivas desde Supuestos)
A25: CAPEX PV = kWp×1000×USD/Wp×FX | B25: =$B$6*1000*Supuestos!$F$33*Supuestos!$B$5 -> 11048734 | C25: CAPEX BESS = kWh×USD/kWh×FX | D25: =$F$6*Supuestos!$G$33*Supuestos!$B$5 -> 7223580
A26: CAPEX Capacitor FP (financiador en PPA) | B26: =Supuestos!$H$33 -> 0 | C26: CAPEX TOTAL (compra) | D26: =B25+D25+B26 -> 18272314 | E26: Bajo PPA, el capacitor lo paga el financiador → el cliente no desembolsa
A28: 3. ENTRADAS MENSUALES (AZUL = datos del recibo / recurso 2025)
A29: Mes | B29: kWh Base | C29: kWh Int | D29: kWh Punta | E29: Días | F29: Dem Pta kW | G29: Dem Máx kW | H29: T.Int $ | I29: T.Base $ | J29: T.Pta $ | K29: T.Cap $ | L29: T.Dist $ | M29: T.Fijo $ | N29: Rend | O29: %AC | P29: HrsP | Q29: DíasP | R29: Bonif FP
A30: Ene | B30: 881325 | C30: 1481542 | D30: 365971 | E30: 31 | F30: 4272 | G30: 4350 | H30: 1.819675 | I30: 1.10665 | J30: 2.1272 | K30: 402.0725 | L30: 86.15 | M30: 703.36 | N30: 142.8 | O30: 1 | P30: 4 | Q30: 22 | R30: -6119.9
A31: Feb | B31: 805606 | C31: 1252899 | D31: 303074 | E31: 28 | F31: 4136 | G31: 4251 | H31: 1.819675 | I31: 1.10665 | J31: 2.1272 | K31: 402.0725 | L31: 86.15 | M31: 703.36 | N31: 139.1 | O31: 1 | P31: 4 | Q31: 19 | R31: -2405.6
A32: Mar | B32: 960995 | C32: 1426117 | D32: 335764 | E32: 31 | F32: 4183 | G32: 4350 | H32: 1.819675 | I32: 1.10665 | J32: 2.1272 | K32: 402.0725 | L32: 86.15 | M32: 703.36 | N32: 170.1 | O32: 1 | P32: 4 | Q32: 20 | R32: -31043.08
A33: Abr | B33: 891289 | C33: 1620825 | D33: 207717 | E33: 30 | F33: 4106 | G33: 4250 | H33: 1.819675 | I33: 1.10665 | J33: 2.1272 | K33: 402.0725 | L33: 86.15 | M33: 703.36 | N33: 150.7 | O33: 1 | P33: 2 | Q33: 22 | R33: -30192.23
A34: May | B34: 960467 | C34: 1696392 | D34: 162699 | E34: 31 | F34: 4081 | G34: 4308 | H34: 1.819675 | I34: 1.10665 | J34: 2.1272 | K34: 402.0725 | L34: 86.15 | M34: 703.36 | N34: 143.1 | O34: 1 | P34: 2 | Q34: 21 | R34: -28885.73
A35: Jun | B35: 923339 | C35: 1593739 | D35: 157968 | E35: 30 | F35: 4146 | G35: 4228 | H35: 1.819675 | I35: 1.10665 | J35: 2.1272 | K35: 402.0725 | L35: 86.15 | M35: 703.36 | N35: 133.9 | O35: 1 | P35: 2 | Q35: 21 | R35: -27370.41
A36: Jul | B36: 765377 | C36: 1464549 | D36: 150284 | E36: 31 | F36: 3935 | G36: 3987 | H36: 1.819675 | I36: 1.10665 | J36: 2.1272 | K36: 402.0725 | L36: 86.15 | M36: 703.36 | N36: 135.2 | O36: 1 | P36: 2 | Q36: 23 | R36: -5877.13
A37: Ago | B37: 900504 | C37: 1602297 | D37: 152370 | E37: 31 | F37: 3868 | G37: 4012 | H37: 1.819675 | I37: 1.10665 | J37: 2.1272 | K37: 402.0725 | L37: 86.15 | M37: 703.36 | N37: 126.5 | O37: 1 | P37: 2 | Q37: 21 | R37: -8586.23
A38: Sep | B38: 746286 | C38: 1358643 | D38: 130996 | E38: 30 | F38: 3761 | G38: 3791 | H38: 1.819675 | I38: 1.10665 | J38: 2.1272 | K38: 402.0725 | L38: 86.15 | M38: 703.36 | N38: 119.5 | O38: 1 | P38: 2 | Q38: 21 | R38: -3056.13
A39: Oct | B39: 754528 | C39: 1417944 | D39: 176270 | E39: 31 | F39: 3121 | G39: 3433 | H39: 1.819675 | I39: 1.10665 | J39: 2.1272 | K39: 402.0725 | L39: 86.15 | M39: 703.36 | N39: 131.7 | O39: 1 | P39: 2 | Q39: 23 | R39: -2237.03
A40: Nov | B40: 756600 | C40: 1150215 | D40: 278429 | E40: 30 | F40: 3661 | G40: 3772 | H40: 1.819675 | I40: 1.10665 | J40: 2.1272 | K40: 402.0725 | L40: 86.15 | M40: 703.36 | N40: 136.6 | O40: 1 | P40: 4 | Q40: 19 | R40: -2622.04
A41: Dic | B41: 741947 | C41: 1178280 | D41: 273186 | E41: 31 | F41: 3968 | G41: 3985 | H41: 1.819675 | I41: 1.10665 | J41: 2.1272 | K41: 402.0725 | L41: 86.15 | M41: 703.36 | N41: 130.9 | O41: 1 | P41: 4 | Q41: 22 | R41: -4631.66
A42: 4. CÁLCULO DE AHORRO MENSUAL (motor — fórmulas que referencian las ENTRADAS)
A43: Mes | B43: Gen kWh | C43: Umbral kW | D43: Autocons | E43: Ah PV ener | F43: Umbral post | G43: Cap base | H43: Cap pre-B | I43: Ah PV dem | J43: Recorte BESS | K43: Cap post | L43: Ah BESS dem | M43: Desc kWh | N43: Arbitraje $ | O43: Fac.AA | P43: mem $ | Q43: Ah PV+BESS
A45: =A30 -> Ene | B45: =$B$6*N30 -> 119867.75 | C45: =(B30+C30+D30)/(E30*24*Supuestos!$B$16) -> 6434.7246 | D45: =MIN(B45*O30,C30) -> 119867.75 | E45: =D45*H30*O45 -> 218120.34 | F45: =((B30+C30+D30)-D45)/(E30*24*Supuestos!$B$16) -> 6152.071 | G45: =MIN(F30,C45) -> 4272 | H45: =MIN(F30,F45) -> 4272 | I45: =(G45-H45)*K30 -> 0 | J45: =IF(P30=0,0,MIN($D$6,$H$6/P30)) -> 345.67199 | K45: =MIN(MAX(F30-J45,0),F45) -> 3926.328 | L45: =(H45-K45)*K30 -> 138985.2 | M45: =IF(P30=0,0,MIN($H$6*Q30,D30)) -> 30419.135 | N45: =M45*J30-(M45/Supuestos!$B$18)*I30 -> 29641.61 | O45: 1 | P45: =M30+B30*I30+C30*H30+D30*J30+G45*K30+MIN(G30,C45)*L30 -> 6542846.3 | Q45: =(E45+I45)+(L45+N45) -> 386747.16
...

Sheet Comparativo Comercial
A1: COMPARATIVO COMERCIAL — Comprar vs PPA / Ahorro Compartido (en vivo)
A2: ⚙ Variables por proyecto (PV/BESS, costo, PPA $/kWh, plazo, comisión) → edítalas en la hoja SUPUESTOS; esta hoja y los flujos de cada sitio se recalculan.
A4: VARIABLES POR PROYECTO (desde Supuestos)
A5: Proyecto | B5: PV kWp | C5: BESS kW | D5: BESS kWh | E5: PPA $/kWh | F5: PPA plazo | G5: Comisión % | H5: Capacitor $
A6: Ixtlahuacán | B6: =Supuestos!$B$28 -> 2529.67 | C6: =Supuestos!$C$28 -> 751.5 | D6: =Supuestos!$D$28 -> 1470 | E6: =Supuestos!$I$28 -> 1.5574 | F6: =Supuestos!$J$28 -> 15 | G6: =Supuestos!$K$28 -> 0.5 | H6: =Supuestos!$H$28 -> 0
A7: Acapulco | B7: =Supuestos!$B$29 -> 1020.305 | C7: =Supuestos!$C$29 -> 250.5 | D7: =Supuestos!$D$29 -> 490 | E7: =Supuestos!$I$29 -> 1.5781 | F7: =Supuestos!$J$29 -> 15 | G7: =Supuestos!$K$29 -> 0.5 | H7: =Supuestos!$H$29 -> 300000
A8: Cancún | B8: =Supuestos!$B$30 -> 839.41 | C8: =Supuestos!$C$30 -> 0 | D8: =Supuestos!$D$30 -> 0 | E8: =Supuestos!$I$30 -> 1.6838 | F8: =Supuestos!$J$30 -> 15 | G8: =Supuestos!$K$30 -> 0.5 | H8: =Supuestos!$H$30 -> 250000
A9: Proplasa PR1 | B9: =Supuestos!$B$31 -> 839.41 | C9: =Supuestos!$C$31 -> 501 | D9: =Supuestos!$D$31 -> 980 | E9: =Supuestos!$I$31 -> 1.5891 | F9: =Supuestos!$J$31 -> 15 | G9: =Supuestos!$K$31 -> 0.5 | H9: =Supuestos!$H$31 -> 0
A10: Proplasa PR2 | B10: =Supuestos!$B$32 -> 1565.135 | C10: =Supuestos!$C$32 -> 1252.5 | D10: =Supuestos!$D$32 -> 2450 | E10: =Supuestos!$I$32 -> 1.6117 | F10: =Supuestos!$J$32 -> 15 | G10: =Supuestos!$K$32 -> 0.5 | H10: =Supuestos!$H$32 -> 0
A11: Proplasa Tapas | B11: =Supuestos!$B$33 -> 839.41 | C11: =Supuestos!$C$33 -> 751.5 | D11: =Supuestos!$D$33 -> 1470 | E11: =Supuestos!$I$33 -> 1.6088 | F11: =Supuestos!$J$33 -> 15 | G11: =Supuestos!$K$33 -> 0.5 | H11: =Supuestos!$H$33 -> 0
A14: RESULTADO POR PROYECTO (beneficio año 1 · TIR)
A15: Proyecto | B15: Compra: benef./año | C15: Compra: inversión | D15: Compra: TIR | E15: PPA: benef. cliente/año | F15: PPA: TIR financiador | G15: Ahorro bruto/año | H15: Ahorro % (proyecto)
A16: Ixtlahuacán | B16: =Ixtlahuacán!$H$79 -> 10237247 | C16: =Ixtlahuacán!$B$106 -> 40520361 | D16: =Ixtlahuacán!$G$100 -> 0.30515621 | E16: =Ixtlahuacán!$K$79 -> 3573170.3 | F16: =Ixtlahuacán!$G$101 -> 0.18294207 | G16: =Ixtlahuacán!$J$72 -> 11170649 | H16: =Ixtlahuacán!$C$21 -> 0.21259287
A17: Acapulco | B17: =Acapulco!$H$79 -> 6070288.6 | C17: =Acapulco!$B$106 -> 16137625 | D17: =Acapulco!$G$100 -> 0.43092559 | E17: =Acapulco!$K$79 -> 3353681.3 | F17: =Acapulco!$G$101 -> 0.18679137 | G17: =Acapulco!$J$72 -> 6212518.3 | H17: =Acapulco!$C$21 -> 0.21986264
A18: Cancún | B18: =Cancún!$H$79 -> 4311691.9 | C18: =Cancún!$B$106 -> 11298734 | D18: =Cancún!$G$100 -> 0.43596923 | E18: =Cancún!$K$79 -> 2462692.9 | F18: =Cancún!$G$101 -> 0.18090212 | G18: =Cancún!$J$72 -> 4331791.9 | H18: =Cancún!$C$21 -> 0.27083319
A19: Proplasa PR1 | B19: ='Proplasa PR1'!$H$79 -> 3792401.4 | C19: ='Proplasa PR1'!$B$106 -> 15864454 | D19: ='Proplasa PR1'!$G$100 -> 0.28566512 | E19: ='Proplasa PR1'!$K$79 -> 1246444.2 | F19: ='Proplasa PR1'!$G$101 -> 0.18105675 | G19: ='Proplasa PR1'!$J$72 -> 4517195.3 | H19: ='Proplasa PR1'!$C$21 -> 0.14038004
A20: Proplasa PR2 | B20: ='Proplasa PR2'!$H$79 -> 7934160.3 | C20: ='Proplasa PR2'!$B$106 -> 32640389 | D20: ='Proplasa PR2'!$G$100 -> 0.28926483 | E20: ='Proplasa PR2'!$K$79 -> 2748991.2 | F20: ='Proplasa PR2'!$G$101 -> 0.17995412 | G20: ='Proplasa PR2'!$J$72 -> 9667366.1 | H20: ='Proplasa PR2'!$C$21 -> 0.094651183
A21: Proplasa Tapas | B21: ='Proplasa Tapas'!$H$79 -> 4480624.8 | C21: ='Proplasa Tapas'!$B$106 -> 18272314 | D21: ='Proplasa Tapas'!$G$100 -> 0.29125501 | E21: ='Proplasa Tapas'!$K$79 -> 1606410.1 | F21: ='Proplasa Tapas'!$G$101 -> 0.1784488 | G21: ='Proplasa Tapas'!$J$72 -> 5506797.3 | H21: ='Proplasa Tapas'!$C$21 -> 0.086688996
A22: PORTAFOLIO | B22: =SUM(B16:B21) -> 36826414 | C22: =SUM(C16:C21) -> 1.3473388e+08 | E22: =SUM(E16:E21) -> 14991390 | G22: =SUM(G16:G21) -> 41406317
A24: Comprar maximiza el ahorro de GEPP (TIR de proyecto 28-44% > costo de capital). El PPA/ahorro compartido = cero inversión/riesgo; la TIR del financiador (18% semilla) es negociable a 14% subiendo el beneficio del cliente. Cambia la tarifa PPA o el plazo en Supuestos y observa el efecto.

Sheet Proyección 20 años
A1: PROYECCIÓN 20 AÑOS — Portafolio GEPP (suma de los 6 medidores, en vivo)
A2: Tarifa Actual = lo que pagarían sin proyecto (con autoabasto hasta 2031; escalón a CFE pleno en 2032). Ahorro persiste; el PV se transfiere al cliente al término del PPA.
A4: Año | B4: Régimen | C4: Tarifa Actual $ | D4: Ahorro total $ | E4: Costo c/proyecto $ | F4: Flujo Compra $ | G4: Flujo Cliente PPA $ | H4: Acum. Compra $ | I4: Acum. Cliente PPA $
A5: 1 | B5: =IF(A5<=6,"Autoabasto","CFE pleno") -> Autoabasto | C5: =Ixtlahuacán!C79+Acapulco!C79+Cancún!C79+'Proplasa PR1'!C79+'Proplasa PR2'!C79+'Proplasa Tapas'!C79 -> 3.1231222e+08 | D5: =(Ixtlahuacán!D79+Ixtlahuacán!E79+Ixtlahuacán!F79)+(Acapulco!D79+Acapulco!E79+Acapulco!F79)+(Cancún!D79+Cancún!E79+Cancún!F79)+('Proplasa PR1'!D79+'Proplasa PR1'!E79+'Proplasa PR1'!F79)+('Proplasa PR2'!D79+'Proplasa PR2'!E79+'Proplasa PR2'!F79)+('Proplasa Tapas'!D79+'Proplasa Tapas'!E79+'Proplasa Tapas'!F79) -> 40427549 | E5: =Ixtlahuacán!G79+Acapulco!G79+Cancún!G79+'Proplasa PR1'!G79+'Proplasa PR2'!G79+'Proplasa Tapas'!G79 -> 2.7188467e+08 | F5: =Ixtlahuacán!H79+Acapulco!H79+Cancún!H79+'Proplasa PR1'!H79+'Proplasa PR2'!H79+'Proplasa Tapas'!H79 -> 36826414 | G5: =Ixtlahuacán!K79+Acapulco!K79+Cancún!K79+'Proplasa PR1'!K79+'Proplasa PR2'!K79+'Proplasa Tapas'!K79 -> 14991390 | H5: =F5 -> 36826414 | I5: =G5 -> 14991390
A6: 2 | B6: =IF(A6<=6,"Autoabasto","CFE pleno") -> Autoabasto | C6: =Ixtlahuacán!C80+Acapulco!C80+Cancún!C80+'Proplasa PR1'!C80+'Proplasa PR2'!C80+'Proplasa Tapas'!C80 -> 3.3105096e+08 | D6: =(Ixtlahuacán!D80+Ixtlahuacán!E80+Ixtlahuacán!F80)+(Acapulco!D80+Acapulco!E80+Acapulco!F80)+(Cancún!D80+Cancún!E80+Cancún!F80)+('Proplasa PR1'!D80+'Proplasa PR1'!E80+'Proplasa PR1'!F80)+('Proplasa PR2'!D80+'Proplasa PR2'!E80+'Proplasa PR2'!F80)+('Proplasa Tapas'!D80+'Proplasa Tapas'!E80+'Proplasa Tapas'!F80) -> 42576570 | E6: =Ixtlahuacán!G80+Acapulco!G80+Cancún!G80+'Proplasa PR1'!G80+'Proplasa PR2'!G80+'Proplasa Tapas'!G80 -> 2.8847439e+08 | F6: =Ixtlahuacán!H80+Acapulco!H80+Cancún!H80+'Proplasa PR1'!H80+'Proplasa PR2'!H80+'Proplasa Tapas'!H80 -> 38759367 | G6: =Ixtlahuacán!K80+Acapulco!K80+Cancún!K80+'Proplasa PR1'!K80+'Proplasa PR2'!K80+'Proplasa Tapas'!K80 -> 15992663 | H6: =H5+F6 -> 75585781 | I6: =I5+G6 -> 30984053
A7: 3 | B7: =IF(A7<=6,"Autoabasto","CFE pleno") -> Autoabasto | C7: =Ixtlahuacán!C81+Acapulco!C81+Cancún!C81+'Proplasa PR1'!C81+'Proplasa PR2'!C81+'Proplasa Tapas'!C81 -> 3.5091401e+08 | D7: =(Ixtlahuacán!D81+Ixtlahuacán!E81+Ixtlahuacán!F81)+(Acapulco!D81+Acapulco!E81+Acapulco!F81)+(Cancún!D81+Cancún!E81+Cancún!F81)+('Proplasa PR1'!D81+'Proplasa PR1'!E81+'Proplasa PR1'!F81)+('Proplasa PR2'!D81+'Proplasa PR2'!E81+'Proplasa PR2'!F81)+('Proplasa Tapas'!D81+'Proplasa Tapas'!E81+'Proplasa Tapas'!F81) -> 44840399 | E7: =Ixtlahuacán!G81+Acapulco!G81+Cancún!G81+'Proplasa PR1'!G81+'Proplasa PR2'!G81+'Proplasa Tapas'!G81 -> 3.0607361e+08 | F7: =Ixtlahuacán!H81+Acapulco!H81+Cancún!H81+'Proplasa PR1'!H81+'Proplasa PR2'!H81+'Proplasa Tapas'!H81 -> 40794164 | G7: =Ixtlahuacán!K81+Acapulco!K81+Cancún!K81+'Proplasa PR1'!K81+'Proplasa PR2'!K81+'Proplasa Tapas'!K81 -> 17056939 | H7: =H6+F7 -> 1.1637994e+08 | I7: =I6+G7 -> 48040992
A8: 4 | B8: =IF(A8<=6,"Autoabasto","CFE pleno") -> Autoabasto | C8: =Ixtlahuacán!C82+Acapulco!C82+Cancún!C82+'Proplasa PR1'!C82+'Proplasa PR2'!C82+'Proplasa Tapas'!C82 -> 3.7196885e+08 | D8: =(Ixtlahuacán!D82+Ixtlahuacán!E82+Ixtlahuacán!F82)+(Acapulco!D82+Acapulco!E82+Acapulco!F82)+(Cancún!D82+Cancún!E82+Cancún!F82)+('Proplasa PR1'!D82+'Proplasa PR1'!E82+'Proplasa PR1'!F82)+('Proplasa PR2'!D82+'Proplasa PR2'!E82+'Proplasa PR2'!F82)+('Proplasa Tapas'!D82+'Proplasa Tapas'!E82+'Proplasa Tapas'!F82) -> 47225198 | E8: =Ixtlahuacán!G82+Acapulco!G82+Cancún!G82+'Proplasa PR1'!G82+'Proplasa PR2'!G82+'Proplasa Tapas'!G82 -> 3.2474366e+08 | F8: =Ixtlahuacán!H82+Acapulco!H82+Cancún!H82+'Proplasa PR1'!H82+'Proplasa PR2'!H82+'Proplasa Tapas'!H82 -> 42936189 | G8: =Ixtlahuacán!K82+Acapulco!K82+Cancún!K82+'Proplasa PR1'!K82+'Proplasa PR2'!K82+'Proplasa Tapas'!K82 -> 18188041 | H8: =H7+F8 -> 1.5931613e+08 | I8: =I7+G8 -> 66229033
